<Environment>
    <QtVersion>@INSERT_QT_VERSION_HERE@</QtVersion>
    <QTestVersion>@INSERT_QT_VERSION_HERE@</QTestVersion>
</Environment>
<TestFunction name="initTestCase">
<Incident type="pass" file="" line="0" />
</TestFunction>
<TestFunction name="testCorrectStdTypes">
<Incident type="pass" file="" line="0" />
</TestFunction>
<TestFunction name="testCorrectStdExceptions">
<Incident type="pass" file="" line="0" />
</TestFunction>
<TestFunction name="testCorrectMyExceptions">
<Incident type="pass" file="" line="0" />
</TestFunction>
<TestFunction name="testFailInt">
<Incident type="fail" file="/home/user/dev/qt5/qtbase/tests/auto/testlib/selftests/verifyexceptionthrown/tst_verifyexceptionthrown.cpp" line="128">
    <Description><![CDATA[Expected exception of type double to be thrown but unknown exception caught]]></Description>
</Incident>
</TestFunction>
<TestFunction name="testFailStdString">
<Incident type="fail" file="/home/user/dev/qt5/qtbase/tests/auto/testlib/selftests/verifyexceptionthrown/tst_verifyexceptionthrown.cpp" line="133">
    <Description><![CDATA[Expected exception of type char* to be thrown but unknown exception caught]]></Description>
</Incident>
</TestFunction>
<TestFunction name="testFailStdRuntimeError">
<Incident type="fail" file="/home/user/dev/qt5/qtbase/tests/auto/testlib/selftests/verifyexceptionthrown/tst_verifyexceptionthrown.cpp" line="138">
    <Description><![CDATA[Expected exception of type std::runtime_error to be thrown but std::exception caught with message: logic error]]></Description>
</Incident>
</TestFunction>
<TestFunction name="testFailMyException">
<Incident type="fail" file="/home/user/dev/qt5/qtbase/tests/auto/testlib/selftests/verifyexceptionthrown/tst_verifyexceptionthrown.cpp" line="143">
    <Description><![CDATA[Expected exception of type MyBaseException to be thrown but std::exception caught with message: logic error]]></Description>
</Incident>
</TestFunction>
<TestFunction name="testFailMyDerivedException">
<Incident type="fail" file="/home/user/dev/qt5/qtbase/tests/auto/testlib/selftests/verifyexceptionthrown/tst_verifyexceptionthrown.cpp" line="148">
    <Description><![CDATA[Expected exception of type std::runtime_error to be thrown but std::exception caught with message: MyDerivedException]]></Description>
</Incident>
</TestFunction>
<TestFunction name="testFailNoException">
<Incident type="fail" file="/home/user/dev/qt5/qtbase/tests/auto/testlib/selftests/verifyexceptionthrown/tst_verifyexceptionthrown.cpp" line="153">
    <Description><![CDATA[Expected exception of type std::exception to be thrown but no exception caught]]></Description>
</Incident>
</TestFunction>
<TestFunction name="cleanupTestCase">
<Incident type="pass" file="" line="0" />
</TestFunction>
